<?xml version="1.0" encoding="utf-8" ?>
<!-- =================================================================================== -->
<!-- |    This document was autogenerated by xacro from /home/miguel/timonhm_ws/src/manipulator_description/robots/timon_arm_hand.urdf.xacro | -->
<!-- |    EDITING THIS FILE BY HAND IS NOT RECOMMENDED                                 | -->
<!-- =================================================================================== -->
<robot name="timon">
    <link name="base_link" />
    <link name="timon_link0">
        <visual>
            <origin rpy="1.571 0 0" xyz="0 0 0" />
            <geometry>
                <mesh filename="package://manipulator_description/meshes/visual/link1.dae" />
            </geometry>
        </visual>
        <collision>
            <origin rpy="1.571 0 0" xyz="0 0 0" />
            <geometry>
                <mesh filename="package://manipulator_description/meshes/visual/link1.dae" />
            </geometry>
        </collision>
        
<inertial>
            <origin rpy="1.571 0 0 " xyz="0 0 0" />
            <mass value="0.856" />
            <inertia ixx="1.26094285e-3" ixy="0.00000e+0" ixz="0.00000e+0" iyy="3.79002180e-4" iyz="-5.78993250e-9" izz="1.26040377e-3" />
        </inertial>

    </link>
    <joint name="base_to_arm" type="fixed">
        <origin rpy="0 0 0" xyz="0 0 0" />
        <parent link="base_link" />
        <child link="timon_link0" />
    </joint>
    <link name="timon_link1">
        <visual>
            <origin rpy="-3.14 0 0" xyz="0 0 0" />
            <geometry>
                <mesh filename="package://manipulator_description/meshes/visual/link2.dae" />
            </geometry>
        </visual>
        <collision>
            <origin rpy="-3.14 0 0" xyz="0 0 0" />
            <geometry>
                <mesh filename="package://manipulator_description/meshes/visual/link2.dae" />
            </geometry>
        </collision>
        
<inertial>
            <origin rpy="-3.14 0 0 " xyz="0 0 0" />
            <mass value="0.15040432" />
            <inertia ixx="3.45063e+1" ixy="0.00000e+0" ixz="0.00000e+0" iyy="1.07762e+2" iyz="0.00000e+0" izz="1.38659e+2" />
        </inertial>

    </link>
    <joint name="timon_joint1" type="continuous">
        <safety_controller k_position="100.0" k_velocity="40.0" />
        <origin rpy="3.14 0 0" xyz="0 0 0.036" />
        <parent link="timon_link0" />
        <child link="timon_link1" />
        <axis rpy="0 0 0" xyz="0 0 1" />
    </joint>
    <link name="timon_link2">
        <visual>
            <origin rpy="1.571 0 0" xyz="0 0 0" />
            <geometry>
                <mesh filename="package://manipulator_description/meshes/visual/link3.dae" />
            </geometry>
        </visual>
        <collision>
            <origin rpy="1.571 0 0" xyz="0 0 0" />
            <geometry>
                <mesh filename="package://manipulator_description/meshes/visual/link3.dae" />
            </geometry>
        </collision>
        
<inertial>
            <origin rpy="1.571 0 0 " xyz="0 0 0" />
            <mass value="0.856" />
            <inertia ixx="1.26094285e-3" ixy="0.00000e+0" ixz="0.00000e+0" iyy="3.79002180e-4" iyz="-5.78993250e-9" izz="1.26040377e-3" />
        </inertial>

    </link>
    <joint name="timon_joint2" type="fixed">
        <origin rpy="-1.571 1.571 1.571" xyz="-0.04 0.0 -0.039" />
        <parent link="timon_link1" />
        <child link="timon_link2" />
    </joint>
    <link name="timon_link3">
        <visual>
            <origin rpy="1.571 0 0" xyz="0 0 0" />
            <geometry>
                <mesh filename="package://manipulator_description/meshes/visual/link4.dae" />
            </geometry>
        </visual>
        <collision>
            <origin rpy="1.571 0 0" xyz="0 0 0" />
            <geometry>
                <mesh filename="package://manipulator_description/meshes/visual/link4.dae" />
            </geometry>
        </collision>
        
<inertial>
            <origin rpy="1.571 0 0 " xyz="0 0 0" />
            <mass value="0.03239855" />
            <inertia ixx="9.57551961e-6" ixy="-1.52519365e-14" ixz="7.17291197e-16" iyy="9.41926366e-6" iyz="1.37735170e-11" izz="1.88295847e-5" />
        </inertial>

    </link>
    <joint name="timon_joint3" type="fixed">
        <origin rpy="1.571 0.0 0.0" xyz="0.0 0.0 -0.093" />
        <parent link="timon_link2" />
        <child link="timon_link3" />
    </joint>
    <link name="timon_link4">
        <visual>
            <origin rpy="0 1.571 0" xyz="-0.0292 0.2289 -0.04" />
            <geometry>
                <mesh filename="package://manipulator_description/meshes/visual/link5.dae" />
            </geometry>
        </visual>
        <collision>
            <origin rpy="0 1.571 0" xyz="-0.0292 0.2289 -0.04" />
            <geometry>
                <mesh filename="package://manipulator_description/meshes/visual/link5.dae" />
            </geometry>
        </collision>
        
<inertial>
            <origin rpy="0 1.571 0 " xyz="-0.0292 0.2289 -0.04" />
            <mass value="1.09212028" />
            <inertia ixx="2.47891806e-2" ixy="-5.41904580e-4" ixz="-2.41956050e-7" iyy="1.48343837e-3" iyz="-8.20873087e-6" izz="2.53662704e-2" />
        </inertial>

    </link>
    <joint name="timon_joint4" type="revolute">
        <safety_controller k_position="100.0" k_velocity="40.0" soft_lower_limit="-1.77" soft_upper_limit="1.77" />
        <origin rpy="0 -1.571 -1.571" xyz="-0.0008 0.093 0.001" />
        <parent link="timon_link3" />
        <child link="timon_link4" />
        <axis xyz="0 0 1" />
        <limit effort="1000.0" lower="-1.77" upper="1.77" velocity="0.5" />
    </joint>
    <link name="timon_link5">
        <visual>
            <origin rpy="0 0 -0.75" xyz="0.0 0.0 0.0" />
            <geometry>
                <mesh filename="package://manipulator_description/meshes/visual/link6.dae" />
            </geometry>
        </visual>
        <collision>
            <origin rpy="0 0 -0.75" xyz="0.0 0.0 0.0" />
            <geometry>
                <mesh filename="package://manipulator_description/meshes/visual/link6.dae" />
            </geometry>
        </collision>
        
<inertial>
            <origin rpy="0 0 -0.75 " xyz="0.0 0.0 0.0" />
            <mass value="0.16505359" />
            <inertia ixx="7.89080915e-5" ixy="-3.13361612e-9" ixz="4.40720922e-9" iyy="4.40037283e-5" iyz="-2.02636752e-6" izz="6.23905424e-5" />
        </inertial>

    </link>
    <joint name="timon_joint5" type="fixed">
        <origin rpy="0 0 0" xyz="0.03 0.451 -0.015" />
        <parent link="timon_link4" />
        <child link="timon_link5" />
    </joint>
    <link name="timon_link6">
        <visual>
            <origin rpy="0 0 0.75" xyz="0.0 0.0 0.0" />
            <geometry>
                <mesh filename="package://manipulator_description/meshes/visual/link7.dae" />
            </geometry>
        </visual>
        <collision>
            <origin rpy="0 0 0.75" xyz="0.0 0.0 0.0" />
            <geometry>
                <mesh filename="package://manipulator_description/meshes/visual/link7.dae" />
            </geometry>
        </collision>
        
<inertial>
            <origin rpy="0 0 0.75 " xyz="0.0 0.0 0.0" />
            <mass value="0.16499216" />
            <inertia ixx="7.88952550e-5" ixy="-3.13065901e-9" ixz="4.40693303e-9" iyy="4.39861799e-5" iyz="-2.02737764e-6" izz="6.23603662e-5" />
        </inertial>

    </link>
    <joint name="timon_joint6" type="fixed">
        <origin rpy="0 3.14 0" xyz="0.0 0.0 -0.05" />
        <parent link="timon_link5" />
        <child link="timon_link6" />
    </joint>
    <link name="timon_link7">
        <visual>
            <origin rpy="0.0 1.571 0.0" xyz="-0.01 0.015 0.0" />
            <geometry>
                <mesh filename="package://manipulator_description/meshes/visual/link8.dae" />
            </geometry>
        </visual>
        <collision>
            <origin rpy="0.0 1.571 0.0" xyz="-0.01 0.015 0.0" />
            <geometry>
                <mesh filename="package://manipulator_description/meshes/visual/link8.dae" />
            </geometry>
        </collision>
        
<inertial>
            <origin rpy="0.0 1.571 0.0" xyz="-0.01 0.015 0.0" />
            <mass value="0.58301843" />
            <inertia ixx="7.66412604e-3" ixy="9.16805313e-10" ixz="2.16130814e-14" iyy="5.98440184e-4" iyz="4.07885374e-6" izz="7.70339943e-3" />
        </inertial>

    </link>
    <joint name="timon_joint7" type="revolute">
        <safety_controller k_position="100.0" k_velocity="40.0" soft_lower_limit="-0.95" soft_upper_limit="2.36" />
        <origin rpy="0.0 0.0 0.0" xyz="0.0 0.001 -0.0375" />
        <parent link="timon_link6" />
        <child link="timon_link7" />
        <axis xyz="0 0 1" />
        <limit effort="1000.0" lower="-0.95" upper="2.36" velocity="0.5" />
    </joint>
    <link name="timon_link8">
        <visual>
            <origin rpy="0.0 0.0 0.0" xyz="0.0 0.0 0.0" />
            <geometry>
                <mesh filename="package://manipulator_description/meshes/visual/link9.dae" />
            </geometry>
        </visual>
        <collision>
            <origin rpy="0.0 0.0 0.0" xyz="0.0 0.0 0.0" />
            <geometry>
                <mesh filename="package://manipulator_description/meshes/visual/link9.dae" />
            </geometry>
        </collision>
        
<inertial>
            <origin rpy="0.0 0.0 0.0" xyz="0.0 0.0 0.0" />
            <mass value="0.16499216" />
            <inertia ixx="7.88952550e-5" ixy="-3.13065901e-9" ixz="4.40693303e-9" iyy="4.39861799e-5" iyz="-2.02737764e-6" izz="6.23603662e-5" />
        </inertial>

    </link>
    <joint name="timon_joint8" type="fixed">
        <origin rpy="0 -1.571 -1.571" xyz="0 0.41 0.013" />
        <parent link="timon_link7" />
        <child link="timon_link8" />
    </joint>
    <link name="timon_link9">
        <visual>
            <origin rpy="1.571 0.0 0.0" xyz="0.0 0.0 0.0" />
            <geometry>
                <mesh filename="package://manipulator_description/meshes/visual/link10.dae" />
            </geometry>
        </visual>
        <collision>
            <origin rpy="1.571 0.0 0.0" xyz="0.0 0.0 0.0" />
            <geometry>
                <mesh filename="package://manipulator_description/meshes/visual/link10.dae" />
            </geometry>
        </collision>
        
<inertial>
            <origin rpy="1.571 0.0 0.0" xyz="0.0 0.0 0.0" />
            <mass value="0.007" />
            <inertia ixx="1.48840827e-6" ixy="2.49592487e-8" ixz="5.30644674e-12" iyy="2.08108627e-6" iyz="2.38181240e-14" izz="6.88193128e-7" />
        </inertial>

    </link>
    <joint name="timon_joint9" type="continuous">
        <origin rpy="0 0 1.571" xyz="0 0 0.025" />
        <parent link="timon_link8" />
        <child link="timon_link9" />
        <axis rpy="0 0 0" xyz="0 0 1" />
    </joint>
    <!-- <link name="${arm_id}_link11">
      <visual>
        <origin xyz="0.0225 -0.007 0.0" rpy="0.0 0.0 0.0" />
        <geometry>
          <mesh filename="package://manipulator_description/meshes/visual/link11.dae"/>
        </geometry>
      </visual>
      <collision>
        <origin xyz="0.0225 -0.007 0.0" rpy="0.0 0.0 0.0" />
        <geometry>
          <mesh filename="package://manipulator_description/meshes/visual/link11.dae"/>
        </geometry>
      </collision>
      
<inertial>
        <origin xyz="0.0225 -0.007 0.0" rpy="0.0 0.0 0.0"/>
        <mass value="0.16499216"/>
        <inertia ixx="7.88952550e-5"  ixy="-3.13065901e-9"  ixz="4.40693303e-9" iyy="4.39861799e-5" iyz="-2.02737764e-6" izz="6.23603662e-5" />
      </inertial>

    </link> 
    <joint name="${arm_id}_joint11" type="fixed">
      <origin rpy="1.5701 0.0 0.0" xyz="0.0 -0.001 0.055"/>
      <parent link="${arm_id}_link10"/>
      <child link="${arm_id}_link11"/>
    </joint>
   

   <link name="${arm_id}_link12">
      <visual>
        <origin xyz="0.0 0.0 0.0" rpy="0.0 1.571 0.0" />
        <geometry>
          <mesh filename="package://manipulator_description/meshes/visual/link12.dae"/>
        </geometry>
      </visual>
      <collision>
        <origin xyz="0.0 0.0 0.0" rpy="0.0 1.571 0.0" />
        <geometry>
          <mesh filename="package://manipulator_description/meshes/visual/link12.dae"/>
        </geometry>
      </collision>
      
<inertial>
        <origin xyz="0.0 0.0 0.0" rpy="0.0 1.571 0.0"/>
        <mass value="0.01873963"/>
        <inertia ixx="4.49588271e-6"  ixy="0.00000000e+0"  ixz="0.00000000e+0" iyy="1.08113872e-5" iyz="0.00000000e+0" izz="1.12040418e-5" />
      </inertial>

    </link> 
    <joint name="${arm_id}_joint12" type="revolute">
      <safety_controller k_position="100.0" k_velocity="40.0" soft_lower_limit="-1.90" soft_upper_limit="1.90"/>
      <origin rpy="0.0 0.0 0.0" xyz="0.0 0.0 0.0"/>
      <parent link="${arm_id}_link11"/>
      <child link="${arm_id}_link12"/>
      <axis xyz="0 0 1"/>
      <limit effort="1000.0" lower="-1.90" upper="1.90" velocity="0.5"/>
    </joint>  -->
    <joint name="timon_hand_joint" type="fixed">
        <parent link="timon_link9" />
        <child link="timon_hand" />
        <origin rpy="1.5701 0.0 0.0" xyz="0.0 -0.001 0.055" />
    </joint>
    <link name="timon_hand">
        <visual>
            <origin rpy="0.0 0.0 0.0" xyz="0.0225 -0.007 0.0" />
            <geometry>
                <mesh filename="package://manipulator_description/meshes/visual/link11.dae" />
            </geometry>
        </visual>
        <collision>
            <origin rpy="0.0 0.0 0.0" xyz="0.0225 -0.007 0.0" />
            <geometry>
                <mesh filename="package://manipulator_description/meshes/visual/link11.dae" />
            </geometry>
        </collision>
        
<inertial>
            <origin rpy="0.0 0.0 0.0" xyz="0.0225 -0.007 0.0" />
            <mass value="0.16499216" />
            <inertia ixx="7.88952550e-5" ixy="-3.13065901e-9" ixz="4.40693303e-9" iyy="4.39861799e-5" iyz="-2.02737764e-6" izz="6.23603662e-5" />
        </inertial>

    </link>
    <link name="timon_hand1">
        <visual>
            <origin rpy="0.0 1.571 0.0" xyz="0.0 0.0 0.0" />
            <geometry>
                <mesh filename="package://manipulator_description/meshes/visual/link12.dae" />
            </geometry>
        </visual>
        <collision>
            <origin rpy="0.0 1.571 0.0" xyz="0.0 0.0 0.0" />
            <geometry>
                <mesh filename="package://manipulator_description/meshes/visual/link12.dae" />
            </geometry>
        </collision>
        
<inertial>
            <origin rpy="0.0 1.571 0.0" xyz="0.0 0.0 0.0" />
            <mass value="0.01873963" />
            <inertia ixx="4.49588271e-6" ixy="0.00000000e+0" ixz="0.00000000e+0" iyy="1.08113872e-5" iyz="0.00000000e+0" izz="1.12040418e-5" />
        </inertial>

    </link>
    <joint name="timon_hand_joint_1" type="revolute">
        <safety_controller k_position="100.0" k_velocity="40.0" soft_lower_limit="-1.90" soft_upper_limit="1.90" />
        <origin rpy="0.0 0.0 0.0" xyz="0.0 0.0 0.0" />
        <parent link="timon_hand" />
        <child link="timon_hand1" />
        <axis xyz="0 0 1" />
        <limit effort="1000.0" lower="-1.90" upper="1.90" velocity="0.5" />
    </joint>
    
<transmission name="trans_timon_joint1">
        <type>transmission_interface/SimpleTransmission</type>
        <joint name="timon_joint1">
            <hardwareInterface>hardware_interface/PositionJointInterface</hardwareInterface>
        </joint>
        <actuator name="timon_joint1_motor">
            <hardwareInterface>hardware_interface/PositionJointInterface</hardwareInterface>
            <mechanicalReduction>1</mechanicalReduction>
        </actuator>
    </transmission>
    <transmission name="trans_timon_joint4">
        <type>transmission_interface/SimpleTransmission</type>
        <joint name="timon_joint4">
            <hardwareInterface>hardware_interface/PositionJointInterface</hardwareInterface>
        </joint>
        <actuator name="timon_joint4_motor">
            <hardwareInterface>hardware_interface/PositionJointInterface</hardwareInterface>
            <mechanicalReduction>1</mechanicalReduction>
        </actuator>
    </transmission>
    <transmission name="trans_timon_joint7">
        <type>transmission_interface/SimpleTransmission</type>
        <joint name="timon_joint7">
            <hardwareInterface>hardware_interface/PositionJointInterface</hardwareInterface>
        </joint>
        <actuator name="timon_joint7_motor">
            <hardwareInterface>hardware_interface/PositionJointInterface</hardwareInterface>
            <mechanicalReduction>1</mechanicalReduction>
        </actuator>
    </transmission>
    <transmission name="trans_timon_joint9">
        <type>transmission_interface/SimpleTransmission</type>
        <joint name="timon_joint9">
            <hardwareInterface>hardware_interface/PositionJointInterface</hardwareInterface>
        </joint>
        <actuator name="timon_joint9_motor">
            <hardwareInterface>hardware_interface/PositionJointInterface</hardwareInterface>
            <mechanicalReduction>1</mechanicalReduction>
        </actuator>
    </transmission>
    <transmission name="trans_timon_hand_joint_1">
        <type>transmission_interface/SimpleTransmission</type>
        <joint name="timon_hand_joint_1">
            <hardwareInterface>hardware_interface/EffortJointInterface</hardwareInterface>
        </joint>
        <actuator name="timon_hand_joint_1_motor">
            <hardwareInterface>hardware_interface/EffortJointInterface</hardwareInterface>
            <mechanicalReduction>1</mechanicalReduction>
        </actuator>
    </transmission>
    <gazebo>
        <plugin name="gazebo_ros_control" filename="libgazebo_ros_control.so">
            <robotNamespace>/</robotNamespace>
        </plugin>
    </gazebo>
</robot>