<?xml version='1.0' encoding='utf-8'?>
<robot xmlns:xacro="http://www.ros.org/wiki/xacro" name="timon">
  <xacro:macro name="timon_arm" params="arm_id:='timon' description_pkg:='manipulator_description' connected_to:='' xyz:='0 0 0' rpy:='0 0 0'">
    <link name="invisible_link">
      <visual>
        <origin xyz="0 0 0" rpy="0 0 0" />
        <geometry>
          <box size="0.000001 0.000001 0.000001"/>
        </geometry>
      </visual>
      <collision>
        <origin xyz="0 0 0" rpy="0 0 0" />
        <geometry>
          <box size="0.000001 0.000001 0.000001"/>
        </geometry>
      </collision>
    </link>
    <link name="${arm_id}_link0">
      <visual>
        <origin xyz="0 0 0" rpy="0 0 0" />
        <geometry>
          <mesh filename="package://${description_pkg}/meshes/JeRoTIMON/id_1.dae"/>
        </geometry>
      </visual>
      <collision>
        <origin xyz="0 0 0" rpy="0 0 0" />
        <geometry>
          <mesh filename="package://${description_pkg}/meshes/JeRoTIMON/id_1.dae"/>
        </geometry>
      </collision>
      <inertial>
        <origin xyz="0 0 0" rpy="0 0 0 "/>
        <mass value="3.72486532"/>
        <inertia ixx="0.011"  ixy="-9.466e-9"  ixz="-0.00000563" iyy="0.04868026" iyz="0" izz="0.05388592" />
      </inertial>
    </link>
     <joint name ="invisble_joint" type="fixed">
        <origin rpy="0 0 0" xyz="0 0 0"/>
        <parent link="invisible_link"/>
        <child link = "${arm_id}_link0"/>
      </joint>

    <link name="${arm_id}_link1">
      <visual>
        <origin xyz="0 0 0" rpy="0 0 0" />
        <geometry>
          <mesh filename="package://${description_pkg}/meshes/JeRoTIMON/id_2.dae"/>
        </geometry>
      </visual>
      <collision>
        <origin xyz="0 0 0" rpy="0 0 0" />
        <geometry>
          <mesh filename="package://${description_pkg}/meshes/JeRoTIMON/id_2.dae"/>
        </geometry>
      </collision>
      <inertial>
        <origin xyz="0 0 0" rpy="0 0 0 "/>
        <mass value="1.00643107"/>
        <inertia ixx="0.00055282"  ixy="0"  ixz="-0.00005159" iyy="0.00152712" iyz="0.00000e+0" izz="0.00141817" />   
      </inertial>
    </link>
    <joint name="${arm_id}_joint1" type="continuous">
      <safety_controller k_position="100.0" k_velocity="40.0"/>
      <origin rpy="0 0 0" xyz="0 0 0.12715351"/>
      <parent link="${arm_id}_link0"/>
      <child link="${arm_id}_link1"/>
      <axis xyz="0 0 1" rpy="0 0 0"/>
    </joint>
 
    <link name="${arm_id}_link2">
      <visual>
        <origin xyz="0 0 0" rpy="0 0 0" />
        <geometry>
          <mesh filename="package://${description_pkg}/meshes/JeRoTIMON/id_3.dae"/>
        </geometry>
      </visual>
      <collision>
        <origin xyz="0 0 0" rpy="0 0 0" />
        <geometry>
          <mesh filename="package://${description_pkg}/meshes/JeRoTIMON/id_3.dae"/>
        </geometry>
      </collision>
      <inertial>
        <origin xyz="0 0 0" rpy="0 0 0 "/>
        <mass value="1.96131158"/>
        <inertia ixx="0.0593682"  ixy="0.00019981"  ixz="0.0024082" iyy="0.06052018" iyz="-0.00320203" izz="0.00314458" />  
      </inertial>
    </link>
    <joint name="${arm_id}_joint2" type="continuous">
      <origin rpy="0 0 0" xyz="0 0 0.03900000"/>
      <parent link="${arm_id}_link1"/>
      <child link="${arm_id}_link2"/>
      <axis xyz="-1 0 0" rpy="0 0 0"/>
    </joint>

    <link name="${arm_id}_link3">
      <visual>
        <origin xyz="0 0 0" rpy="0 0 0" />
        <geometry>
          <mesh filename="package://${description_pkg}/meshes/JeRoTIMON/id_4.dae"/>
        </geometry>
      </visual>
      <collision>
        <origin xyz="0 0 0" rpy="0 0 0" />
        <geometry>
          <mesh filename="package://${description_pkg}/meshes/JeRoTIMON/id_4.dae"/>
        </geometry>
      </collision>
      <inertial>
        <origin xyz="0 0 0" rpy="0 0 0 "/>
        <mass value="1.96131158"/>
        <inertia ixx="0.0593682"  ixy="0.00019981"  ixz="0.0024082" iyy="0.06052018" iyz="-0.00320203" izz="0.00314458" /> 
      </inertial>
    </link>
    <joint name="${arm_id}_joint3" type="continuous">
      <origin rpy="0 0.0 0.0" xyz="0 0.02683555 0.46242180"/>
      <parent link="${arm_id}_link2"/>
      <child link="${arm_id}_link3"/>
      <axis xyz="-1 0 0" rpy="0 0 0"/>
    </joint>

    <link name="${arm_id}_link4">
      <visual>
        <origin xyz="0 0 0" rpy="0 0 0" />
        <geometry>
          <mesh filename="package://${description_pkg}/meshes/JeRoTIMON/id_5.dae"/>
        </geometry>
      </visual>
      <collision>
        <origin xyz="0 0 0" rpy="0 0 0" />
        <geometry>
          <mesh filename="package://${description_pkg}/meshes/JeRoTIMON/id_5.dae"/>
        </geometry>
      </collision>
      <inertial>
        <origin xyz="0 0 0" rpy="0 0 0 "/>
        <mass value="0.37561629"/>
        <inertia ixx="0.00025385"  ixy="0"  ixz="0" iyy="0.00011288" iyz="0.00000228" izz="0.00025011" /> 
      </inertial>
    </link>
    <joint name="${arm_id}_joint4" type="revolute">
      <safety_controller k_position="100.0" k_velocity="40.0" soft_lower_limit="-1.77" soft_upper_limit="1.77"/>
      <origin rpy="0 0 0" xyz="0.00739115 -0.03075115 0.44053087"/>
      <parent link="${arm_id}_link3"/>
      <child link="${arm_id}_link4"/>
      <axis xyz="0 0 1"/>
      <limit effort="1000.0" lower="-1.77" upper="1.77" velocity="0.5"/>
    </joint>
<!--
    <link name="${arm_id}_link5">
      <visual>
        <origin xyz="0.0 0.0 0.0" rpy="0 0 -0.75" />
        <geometry>
          <mesh filename="package://${description_pkg}/meshes/visual/link6.dae"/>
        </geometry>
      </visual>
      <collision>
        <origin xyz="0.0 0.0 0.0" rpy="0 0 -0.75" />
        <geometry>
          <mesh filename="package://${description_pkg}/meshes/visual/link6.dae"/>
        </geometry>
      </collision>
      <inertial>
        <origin xyz="0.0 0.0 0.0" rpy="0 0 -0.75 "/>
        <mass value="0.16505359"/>
        <inertia ixx="7.89080915e-5"  ixy="-3.13361612e-9"  ixz="4.40720922e-9" iyy="4.40037283e-5" iyz="-2.02636752e-6" izz="6.23905424e-5" />
      </inertial>
    </link>
    <joint name="${arm_id}_joint5" type="fixed">
      <origin rpy="0 0 0" xyz="0.03 0.451 -0.015"/>
      <parent link="${arm_id}_link4"/>
      <child link="${arm_id}_link5"/>
    </joint>

    <link name="${arm_id}_link6">
      <visual>
        <origin xyz="0.0 0.0 0.0" rpy="0 0 0.75" />
        <geometry>
          <mesh filename="package://${description_pkg}/meshes/visual/link7.dae"/>
        </geometry>
      </visual>
      <collision>
        <origin xyz="0.0 0.0 0.0" rpy="0 0 0.75" />
        <geometry>
          <mesh filename="package://${description_pkg}/meshes/visual/link7.dae"/>
        </geometry>
      </collision>
      <inertial>
        <origin xyz="0.0 0.0 0.0" rpy="0 0 0.75 "/>
        <mass value="0.16499216"/>
        <inertia ixx="7.88952550e-5"  ixy="-3.13065901e-9"  ixz="4.40693303e-9" iyy="4.39861799e-5" iyz="-2.02737764e-6" izz="6.23603662e-5" />
      </inertial>
    </link>
    <joint name="${arm_id}_joint6" type="fixed">
      <origin rpy="0 3.14 0" xyz="0.0 0.0 -0.05"/>
      <parent link="${arm_id}_link5"/>
      <child link="${arm_id}_link6"/>
    </joint>

    <link name="${arm_id}_link7">
      <visual>
        <origin xyz="-0.01 0.015 0.0" rpy="0.0 1.571 0.0" />
        <geometry>
          <mesh filename="package://${description_pkg}/meshes/visual/link8.dae"/>
        </geometry>
      </visual>
      <collision>
        <origin xyz="-0.01 0.015 0.0" rpy="0.0 1.571 0.0" />
        <geometry>
          <mesh filename="package://${description_pkg}/meshes/visual/link8.dae"/>
        </geometry>
      </collision>
      <inertial>
        <origin xyz="-0.01 0.015 0.0" rpy="0.0 1.571 0.0"/>
        <mass value="0.58301843"/>
        <inertia ixx="7.66412604e-3"  ixy="9.16805313e-10"  ixz="2.16130814e-14" iyy="5.98440184e-4" iyz="4.07885374e-6" izz="7.70339943e-3" />
      </inertial>
    </link>
    <joint name="${arm_id}_joint7" type="revolute">
      <safety_controller k_position="100.0" k_velocity="40.0" soft_lower_limit="-0.95" soft_upper_limit="2.36"/>
      <origin rpy="0.0 0.0 0.0" xyz="0.0 0.001 -0.0375"/>
      <parent link="${arm_id}_link6"/>
      <child link="${arm_id}_link7"/>
      <axis xyz="0 0 1"/>
      <limit effort="1000.0" lower="-0.95" upper="2.36" velocity="0.5"/>
    </joint>

    <link name="${arm_id}_link8">
      <visual>
        <origin xyz="0.0 0.0 0.0" rpy="0.0 0.0 0.0" />
        <geometry>
          <mesh filename="package://manipulator_description/meshes/visual/link9.dae"/>
        </geometry>
      </visual>
      <collision>
        <origin xyz="0.0 0.0 0.0" rpy="0.0 0.0 0.0" />
        <geometry>
          <mesh filename="package://manipulator_description/meshes/visual/link9.dae"/>
        </geometry>
      </collision>
      <inertial>
        <origin xyz="0.0 0.0 0.0" rpy="0.0 0.0 0.0"/>
        <mass value="0.16499216"/>
        <inertia ixx="7.88952550e-5"  ixy="-3.13065901e-9"  ixz="4.40693303e-9" iyy="4.39861799e-5" iyz="-2.02737764e-6" izz="6.23603662e-5" />
      </inertial>
    </link>
    <joint name="${arm_id}_joint8" type="fixed">
      <origin rpy="0 -1.571 -1.571" xyz="0 0.41 0.013"/>
      <parent link="${arm_id}_link7"/>
      <child link="${arm_id}_link8"/>
    </joint>

    <link name="${arm_id}_link9">
      <visual>
        <origin xyz="0.0 0.0 0.0" rpy="1.571 0.0 0.0" />
        <geometry>
          <mesh filename="package://manipulator_description/meshes/visual/link10.dae"/>
        </geometry>
      </visual>
      <collision>
        <origin xyz="0.0 0.0 0.0" rpy="1.571 0.0 0.0" />
        <geometry>
          <mesh filename="package://manipulator_description/meshes/visual/link10.dae"/>
        </geometry>
      </collision>
      <inertial>
        <origin xyz="0.0 0.0 0.0" rpy="1.571 0.0 0.0"/>
        <mass value="0.007"/>
        <inertia ixx="1.48840827e-6"  ixy="2.49592487e-8"  ixz="5.30644674e-12" iyy="2.08108627e-6" iyz="2.38181240e-14" izz="6.88193128e-7" />
      </inertial>
    </link>
    <joint name="${arm_id}_joint9" type="continuous">
      <origin rpy="0 0 1.571" xyz="0 0 0.025"/>
      <parent link="${arm_id}_link8"/>
      <child link="${arm_id}_link9"/>
      <axis xyz="0 0 1" rpy="0 0 0"/>
    </joint>
    
    <link name="${arm_id}_link10">
      <visual>
        <origin xyz="0.0225 -0.007 0.0" rpy="0.0 0.0 0.0" />
        <geometry>
          <mesh filename="package://manipulator_description/meshes/visual/link11.dae"/>
        </geometry>
      </visual>
      <collision>
        <origin xyz="0.0225 -0.007 0.0" rpy="0.0 0.0 0.0" />
        <geometry>
          <mesh filename="package://manipulator_description/meshes/visual/link11.dae"/>
        </geometry>
      </collision>
      <inertial>
        <origin xyz="0.0225 -0.007 0.0" rpy="0.0 0.0 0.0"/>
        <mass value="0.16499216"/>
        <inertia ixx="7.88952550e-5"  ixy="-3.13065901e-9"  ixz="4.40693303e-9" iyy="4.39861799e-5" iyz="-2.02737764e-6" izz="6.23603662e-5" />
      </inertial>
    </link> 
    <joint name="${arm_id}_joint10" type="fixed">
      <origin rpy="1.5701 0.0 0.0" xyz="0.0 -0.001 0.055"/>
      <parent link="${arm_id}_link9"/>
      <child link="${arm_id}_link10"/>
    </joint>
   

   <link name="${arm_id}_link11">
      <visual>
        <origin xyz="0.0 0.0 0.0" rpy="0.0 1.571 0.0" />
        <geometry>
          <mesh filename="package://manipulator_description/meshes/visual/link12.dae"/>
        </geometry>
      </visual>
      <collision>
        <origin xyz="0.0 0.0 0.0" rpy="0.0 1.571 0.0" />
        <geometry>
          <mesh filename="package://manipulator_description/meshes/visual/link12.dae"/>
        </geometry>
      </collision>
      <inertial>
        <origin xyz="0.0 0.0 0.0" rpy="0.0 1.571 0.0"/>
        <mass value="0.01873963"/>
        <inertia ixx="4.49588271e-6"  ixy="0.00000000e+0"  ixz="0.00000000e+0" iyy="1.08113872e-5" iyz="0.00000000e+0" izz="1.12040418e-5" />
      </inertial>
    </link> 
    <joint name="${arm_id}_joint11" type="revolute">
      <safety_controller k_position="100.0" k_velocity="40.0" soft_lower_limit="-1.90" soft_upper_limit="1.90"/>
      <origin rpy="0.0 0.0 0.0" xyz="0.0 0.0 0.0"/>
      <parent link="${arm_id}_link10"/>
      <child link="${arm_id}_link11"/>
      <axis xyz="0 0 1"/>
      <limit effort="1000.0" lower="-1.90" upper="1.90" velocity="0.5"/>
    </joint> 
    
    <transmission name="trans_timon_joint1">
        <type>transmission_interface/SimpleTransmission</type>
        <joint name="timon_joint1">
            <hardwareInterface>hardware_interface/PositionJointInterface</hardwareInterface>
        </joint>
        <actuator name="timon_joint1_motor">
            <hardwareInterface>hardware_interface/PositionJointInterface</hardwareInterface>
            <mechanicalReduction>1</mechanicalReduction>
        </actuator>
    </transmission>
    <transmission name="trans_timon_joint4">
        <type>transmission_interface/SimpleTransmission</type>
        <joint name="timon_joint4">
            <hardwareInterface>hardware_interface/PositionJointInterface</hardwareInterface>
        </joint>
        <actuator name="timon_joint4_motor">
            <hardwareInterface>hardware_interface/PositionJointInterface</hardwareInterface>
            <mechanicalReduction>1</mechanicalReduction>
        </actuator>
    </transmission>
    <transmission name="trans_timon_joint7">
        <type>transmission_interface/SimpleTransmission</type>
        <joint name="timon_joint7">
            <hardwareInterface>hardware_interface/PositionJointInterface</hardwareInterface>
        </joint>
        <actuator name="timon_joint7_motor">
            <hardwareInterface>hardware_interface/PositionJointInterface</hardwareInterface>
            <mechanicalReduction>1</mechanicalReduction>
        </actuator>
    </transmission>
    <transmission name="trans_timon_joint9">
        <type>transmission_interface/SimpleTransmission</type>
        <joint name="timon_joint9">
            <hardwareInterface>hardware_interface/PositionJointInterface</hardwareInterface>
        </joint>
        <actuator name="timon_joint9_motor">
            <hardwareInterface>hardware_interface/PositionJointInterface</hardwareInterface>
            <mechanicalReduction>1</mechanicalReduction>
        </actuator>
    </transmission>
    <transmission name="trans_timon_joint11">
        <type>transmission_interface/SimpleTransmission</type>
        <joint name="timon_joint11">
            <hardwareInterface>hardware_interface/PositionJointInterface</hardwareInterface>
        </joint>
        <actuator name="timon_joint11_motor">
            <hardwareInterface>hardware_interface/PositionJointInterface</hardwareInterface>
            <mechanicalReduction>1</mechanicalReduction>
        </actuator>
    </transmission> -->
 

  </xacro:macro>
</robot>